// src/components/error/__tests__/ErrorBoundary.test.tsx
import { render, screen } from '@testing-library/react';
import { ErrorBoundary } from '../ErrorBoundary';

const ThrowError = () => {
  throw new Error('Test error');
};

describe('ErrorBoundary', () => {
  it('renders children when there is no error', () => {
    render(
      <ErrorBoundary>
        <div>Test content</div>
      </ErrorBoundary>
    );

    expect(screen.getByText('Test content')).toBeInTheDocument();
  });

  it('renders error UI when error is thrown', () => {
    // Suppress console.error for this test
    const spy = jest.spyOn(console, 'error');
    spy.mockImplementation(() => {});

    render(
      <ErrorBoundary>
        <ThrowError />
      </ErrorBoundary>
    );

    expect(screen.getByText('Something went wrong')).toBeInTheDocument();
    expect(screen.getByText('Test error')).toBeInTheDocument();

    spy.mockRestore();
  });

  it('renders custom fallback when provided', () => {
    const spy = jest.spyOn(console, 'error');
    spy.mockImplementation(() => {});

    render(
      <ErrorBoundary fallback={<div>Custom error message</div>}>
        <ThrowError />
      </ErrorBoundary>
    );

    expect(screen.getByText('Custom error message')).toBeInTheDocument();

    spy.mockRestore();
  });
});
